<sdf version='1.6'>
  <world name='default'>
    <light name='sun' type='directional'>
      <cast_shadows>1</cast_shadows>
      <pose frame=''>0 0 10 0 -0 0</pose>
      <diffuse>0.8 0.8 0.8 1</diffuse>
      <specular>0.2 0.2 0.2 1</specular>
      <attenuation>
        <range>1000</range>
        <constant>0.9</constant>
        <linear>0.01</linear>
        <quadratic>0.001</quadratic>
      </attenuation>
      <direction>-0.5 0.1 -0.9</direction>
    </light>
    <model name='ground_plane'>
      <static>1</static>
      <link name='link'>
        <collision name='collision'>
          <geometry>
            <plane>
              <normal>0 0 1</normal>
              <size>100 100</size>
            </plane>
          </geometry>
          <surface>
            <friction>
              <ode>
                <mu>100</mu>
                <mu2>50</mu2>
              </ode>
              <torsional>
                <ode/>
              </torsional>
            </friction>
            <contact>
              <ode/>
            </contact>
            <bounce/>
          </surface>
          <max_contacts>10</max_contacts>
        </collision>
        <visual name='visual'>
          <cast_shadows>0</cast_shadows>
          <geometry>
            <plane>
              <normal>0 0 1</normal>
              <size>100 100</size>
            </plane>
          </geometry>
          <material>
            <script>
              <uri>file://media/materials/scripts/gazebo.material</uri>
              <name>Gazebo/Grey</name>
            </script>
          </material>
        </visual>
        <self_collide>0</self_collide>
        <enable_wind>0</enable_wind>
        <kinematic>0</kinematic>
      </link>
    </model>
    <gravity>0 0 -9.8</gravity>
    <magnetic_field>6e-06 2.3e-05 -4.2e-05</magnetic_field>
    <atmosphere type='adiabatic'/>
    <physics name='default_physics' default='0' type='ode'>
      <max_step_size>0.001</max_step_size>
      <real_time_factor>1</real_time_factor>
      <real_time_update_rate>1000</real_time_update_rate>
    </physics>
    <scene>
      <ambient>0.4 0.4 0.4 1</ambient>
      <background>0.7 0.7 0.7 1</background>
      <shadows>1</shadows>
    </scene>
    <audio>
      <device>default</device>
    </audio>
    <wind/>
    <spherical_coordinates>
      <surface_model>EARTH_WGS84</surface_model>
      <latitude_deg>0</latitude_deg>
      <longitude_deg>0</longitude_deg>
      <elevation>0</elevation>
      <heading_deg>0</heading_deg>
    </spherical_coordinates>
    <state world_name='default'>
      <sim_time>1714 198000000</sim_time>
      <real_time>113 427629972</real_time>
      <wall_time>1580328531 386243017</wall_time>
      <iterations>53398</iterations>
      <model name='ground_plane'>
        <pose frame=''>0 0 0 0 -0 0</pose>
        <scale>1 1 1</scale>
        <link name='link'>
          <pose frame=''>0 0 0 0 -0 0</pose>
          <velocity>0 0 0 0 -0 0</velocity>
          <acceleration>0 0 0 0 -0 0</acceleration>
          <wrench>0 0 0 0 -0 0</wrench>
        </link>
      </model>
      <model name='my_robot'>
        <pose frame=''>14.8614 -6.36609 0.100003 2e-06 -8e-06 -6.4e-05</pose>
        <scale>1 1 1</scale>
        <link name='camera::link'>
          <pose frame=''>14.6614 -6.36608 0.25 -2e-06 6e-06 3.13994</pose>
          <velocity>0.000813 -0.000174 5.5e-05 0.000971 -0.000404 9.4e-05</velocity>
          <acceleration>-0.035413 -0.348079 0.109733 1.94198 -0.807719 0.189607</acceleration>
          <wrench>-0.003541 -0.034808 0.010973 0 -0 0</wrench>
        </link>
        <link name='chassis'>
          <pose frame=''>14.8614 -6.36609 0.200003 2e-06 -8e-06 -6.4e-05</pose>
          <velocity>0.000833 -0.000183 0.000139 0.000944 -0.000409 -1.4e-05</velocity>
          <acceleration>0.004919 -0.366066 0.278546 1.88784 -0.818859 -0.027311</acceleration>
          <wrench>0.004919 -0.366066 0.278546 0 -0 0</wrench>
        </link>
        <link name='hokuyo::link'>
          <pose frame=''>14.6414 -6.36608 0.350001 -2e-06 8e-06 3.13994</pose>
          <velocity>0.000772 -0.000321 4.9e-05 0.000944 -0.000409 -1.4e-05</velocity>
          <acceleration>-0.117953 -0.641375 0.098367 1.8876 -0.818992 -0.027372</acceleration>
          <wrench>-0.011795 -0.064137 0.009837 0 -0 0</wrench>
        </link>
        <link name='left_wheel'>
          <pose frame=''>15.0614 -6.0461 0.200004 1.57025 1.41925 3.14088</pose>
          <velocity>0.000837 -0.000189 0.000524 0.000944 0.004183 -1.4e-05</velocity>
          <acceleration>0.012515 -0.377034 1.04719 1.88687 -2.8e-05 -0.027411</acceleration>
          <wrench>0.012515 -0.377034 1.04719 0 -0 0</wrench>
        </link>
        <link name='right_wheel'>
          <pose frame=''>15.0614 -6.6861 0.200004 1.57025 1.42036 3.14087</pose>
          <velocity>0.00083 -0.000189 -8.3e-05 0.000944 0.004162 -1.4e-05</velocity>
          <acceleration>-0.002132 -0.377361 -0.16519 1.88668 -0.000153 -0.02733</acceleration>
          <wrench>-0.002132 -0.377361 -0.16519 0 -0 0</wrench>
        </link>
      </model>
      <model name='my_robot_four'>
        <pose frame=''>16.6881 -7.53341 0.100005 -0 3e-06 0.006638</pose>
        <scale>1 1 1</scale>
        <link name='chassis'>
          <pose frame=''>16.6881 -7.53341 0.300005 -0 3e-06 0.006638</pose>
          <velocity>-5e-06 -0.000122 0.003149 0.000555 -0.005623 1.7e-05</velocity>
          <acceleration>-1.19104 -0.319687 5.86694 -1.8813 -0.139942 3.10972</acceleration>
          <wrench>-1.19104 -0.319687 5.86694 0 -0 0</wrench>
        </link>
        <link name='left_wheel'>
          <pose frame=''>16.936 -7.21176 0.200005 1.56874 1.52619 -3.13711</pose>
          <velocity>0.000537 -9.8e-05 0.004797 0.000494 0.002688 1.6e-05</velocity>
          <acceleration>0.356947 -0.247044 10.2281 1.15103 0.00784 -0.032999</acceleration>
          <wrench>0.356947 -0.247044 10.2281 0 -0 0</wrench>
        </link>
        <link name='left_wheel1'>
          <pose frame=''>16.436 -7.21508 0.200006 1.54902 1.5664 3.12636</pose>
          <velocity>0.000546 -5.9e-05 0.001878 0.000485 0.001027 1.7e-05</velocity>
          <acceleration>0.377674 -0.176011 2.3401 1.12443 0.007499 -0.032593</acceleration>
          <wrench>0.377674 -0.176011 2.3401 0 -0 0</wrench>
        </link>
        <link name='right_wheel'>
          <pose frame=''>16.9402 -7.85175 0.200004 1.56957 1.49804 -3.13628</pose>
          <velocity>0.000581 -9.5e-05 0.004172 0.000479 0.002909 1.8e-05</velocity>
          <acceleration>0.376012 -0.241004 9.11508 1.13756 -0.044671 -0.031488</acceleration>
          <wrench>0.376012 -0.241004 9.11508 0 -0 0</wrench>
        </link>
        <link name='right_wheel1'>
          <pose frame=''>16.4403 -7.85507 0.200006 1.56691 1.54664 -3.13894</pose>
          <velocity>0.000566 -6e-05 0.001597 0.00046 0.001101 1.7e-05</velocity>
          <acceleration>0.349798 -0.187046 1.61735 1.09779 0.007255 -0.033209</acceleration>
          <wrench>0.349798 -0.187046 1.61735 0 -0 0</wrench>
        </link>
      </model>
      <model name='my_robot_six'>
        <pose frame=''>18.2739 -5.6096 0.100006 -4e-06 -0 0.000255</pose>
        <scale>1 1 1</scale>
        <link name='chassis'>
          <pose frame=''>18.2739 -5.6096 0.300006 -4e-06 -0 0.000255</pose>
          <velocity>0.000327 7.7e-05 0.002509 -0.000262 -0.000257 -2.6e-05</velocity>
          <acceleration>-0.066035 -1.10551 4.00979 -2.54858 -0.217187 -0.069587</acceleration>
          <wrench>-0.066035 -1.10551 4.00979 0 -0 0</wrench>
        </link>
        <link name='left_wheel'>
          <pose frame=''>18.7738 -5.28947 0.200004 1.56815 1.53718 3.1391</pose>
          <velocity>0.000369 5.2e-05 0.002546 -0.000262 0.001841 -2.5e-05</velocity>
          <acceleration>-0.014857 -0.759582 5.31603 -2.54664 -0.03596 -0.068737</acceleration>
          <wrench>-0.014857 -0.759582 5.31603 0 -0 0</wrench>
        </link>
        <link name='left_wheel1'>
          <pose frame=''>18.3238 -5.28959 0.200004 1.56816 1.53712 3.13911</pose>
          <velocity>0.000367 5.4e-05 0.002404 -0.000267 0.00183 -2.6e-05</velocity>
          <acceleration>-0.017505 -0.764802 5.2158 -2.55427 0.020078 -0.071392</acceleration>
          <wrench>-0.017505 -0.764802 5.2158 0 -0 0</wrench>
        </link>
        <link name='left_wheel2'>
          <pose frame=''>17.8238 -5.28972 0.200004 1.56795 1.53947 3.1389</pose>
          <velocity>0.000346 5.2e-05 0.002273 -0.000261 0.001724 -2.5e-05</velocity>
          <acceleration>-0.038724 -0.710043 5.13074 -2.54982 0.101882 -0.070157</acceleration>
          <wrench>-0.038724 -0.710043 5.13074 0 -0 0</wrench>
        </link>
        <link name='right_wheel'>
          <pose frame=''>18.774 -5.92947 0.200007 1.56829 1.53536 3.13924</pose>
          <velocity>0.000339 4.2e-05 0.002743 -0.000269 0.002064 -2.7e-05</velocity>
          <acceleration>-0.071546 -0.759482 2.91758 -2.54621 0.000913 -0.069597</acceleration>
          <wrench>-0.071546 -0.759482 2.91758 0 -0 0</wrench>
        </link>
        <link name='right_wheel1'>
          <pose frame=''>18.324 -5.92959 0.200007 1.56826 1.53582 3.13921</pose>
          <velocity>0.000337 4e-05 0.002633 -0.000267 0.002057 -2.5e-05</velocity>
          <acceleration>-0.072543 -0.743742 2.82486 -2.54834 0.000913 -0.069662</acceleration>
          <wrench>-0.072543 -0.743742 2.82486 0 -0 0</wrench>
        </link>
        <link name='right_wheel2'>
          <pose frame=''>17.824 -5.92971 0.200007 1.56825 1.53593 3.1392</pose>
          <velocity>0.000344 4.5e-05 0.002519 -0.000273 0.002141 -2.4e-05</velocity>
          <acceleration>-0.082215 -0.754613 2.7116 -2.55669 0.000911 -0.069239</acceleration>
          <wrench>-0.082215 -0.754613 2.7116 0 -0 0</wrench>
        </link>
        <link name='scooper'>
          <pose frame=''>17.4239 -5.60982 0.200006 4.5e-05 0 0.000255</pose>
          <velocity>0.00035 6.8e-05 0.002259 1e-06 -0.00027 -2.5e-05</velocity>
          <acceleration>-0.04895 -0.667217 3.84408 5.4e-05 -0.211861 -0.073411</acceleration>
          <wrench>-0.04895 -0.667217 3.84408 0 -0 0</wrench>
        </link>
      </model>
      <model name='unit_box'>
        <pose frame=''>2.99998 -9.69812 0.5 0 0 -5e-06</pose>
        <scale>1 1 1</scale>
        <link name='link'>
          <pose frame=''>2.99998 -9.69812 0.5 0 0 -5e-06</pose>
          <velocity>0 0 0 0 -0 0</velocity>
          <acceleration>0 -0 0 1e-06 1e-06 0</acceleration>
          <wrench>0 -0 0 0 -0 0</wrench>
        </link>
      </model>
      <model name='unit_box_0'>
        <pose frame=''>-4.99198 1.77226 0.499995 0 1e-05 0</pose>
        <scale>1 1 1</scale>
        <link name='link'>
          <pose frame=''>-4.99198 1.77226 0.499995 0 1e-05 0</pose>
          <velocity>0 0 0 0 -0 0</velocity>
          <acceleration>0.010615 0.006191 -9.78231 -0.012424 0.021225 -1.8e-05</acceleration>
          <wrench>0.010615 0.006191 -9.78231 0 -0 0</wrench>
        </link>
      </model>
      <model name='unit_box_1'>
        <pose frame=''>5.82102 7.27449 0.499995 0 1e-05 0</pose>
        <scale>1 1 1</scale>
        <link name='link'>
          <pose frame=''>5.82102 7.27449 0.499995 0 1e-05 0</pose>
          <velocity>0 0 0 0 -0 0</velocity>
          <acceleration>0.010615 0.006191 -9.78231 -0.012424 0.021225 -1.8e-05</acceleration>
          <wrench>0.010615 0.006191 -9.78231 0 -0 0</wrench>
        </link>
      </model>
      <model name='unit_box_2_clone'>
        <pose frame=''>-10.4111 -15.4302 1.54268 0 -1e-06 0.006888</pose>
        <scale>1 1 1</scale>
        <link name='link'>
          <pose frame=''>-10.4111 -15.4302 1.54268 0 -1e-06 0.006888</pose>
          <velocity>0 0 0 0 -0 0</velocity>
          <acceleration>2.83984 1.2933 8.73462 2.94327 -0.852358 2.67104</acceleration>
          <wrench>2.83984 1.2933 8.73462 0 -0 0</wrench>
        </link>
      </model>
      <model name='unit_box_2_clone_0'>
        <pose frame=''>-13.9418 8.84197 1.54268 0 -1e-06 0.006888</pose>
        <scale>1 1 1</scale>
        <link name='link'>
          <pose frame=''>-13.9418 8.84197 1.54268 0 -1e-06 0.006888</pose>
          <velocity>0 0 0 0 -0 0</velocity>
          <acceleration>2.83984 1.2933 8.73462 2.94327 -0.852358 2.67104</acceleration>
          <wrench>2.83984 1.2933 8.73462 0 -0 0</wrench>
        </link>
      </model>
      <model name='unit_box_2_clone_1'>
        <pose frame=''>3.28999 -26.3429 1.54268 0 -1e-06 0.006888</pose>
        <scale>1 1 1</scale>
        <link name='link'>
          <pose frame=''>3.28999 -26.3429 1.54268 0 -1e-06 0.006888</pose>
          <velocity>0 0 0 0 -0 0</velocity>
          <acceleration>2.83984 1.2933 8.73462 2.94327 -0.852358 2.67104</acceleration>
          <wrench>2.83984 1.2933 8.73462 0 -0 0</wrench>
        </link>
      </model>
      <model name='unit_box_2_clone_2'>
        <pose frame=''>13.308 7.61794 1.54268 0 -1e-06 0.006888</pose>
        <scale>1 1 1</scale>
        <link name='link'>
          <pose frame=''>13.308 7.61794 1.54268 0 -1e-06 0.006888</pose>
          <velocity>0 0 0 0 -0 0</velocity>
          <acceleration>2.83984 1.2933 8.73462 2.94327 -0.852358 2.67104</acceleration>
          <wrench>2.83984 1.2933 8.73462 0 -0 0</wrench>
        </link>
      </model>
      <model name='unit_box_2_clone_3'>
        <pose frame=''>-22.496 -3.5392 3.16509 0 -1e-06 -0.00039</pose>
        <scale>1 1 1</scale>
        <link name='link'>
          <pose frame=''>-22.496 -3.5392 3.16509 0 -1e-06 -0.00039</pose>
          <velocity>0 0 0 0 -0 0</velocity>
          <acceleration>1.13516 -2.91123 8.60282 -2.7355 0.27473 -2.68997</acceleration>
          <wrench>1.13516 -2.91123 8.60282 0 -0 0</wrench>
        </link>
      </model>
      <model name='unit_box_2_clone_4'>
        <pose frame=''>4.29268 21.3889 3.16509 0 -1e-06 -0.00039</pose>
        <scale>1 1 1</scale>
        <link name='link'>
          <pose frame=''>4.29268 21.3889 3.16509 0 -1e-06 -0.00039</pose>
          <velocity>0 0 0 0 -0 0</velocity>
          <acceleration>1.13516 -2.91123 8.60282 -2.7355 0.27473 -2.68997</acceleration>
          <wrench>1.13516 -2.91123 8.60282 0 -0 0</wrench>
        </link>
      </model>
      <model name='unit_box_2_clone_5'>
        <pose frame=''>23.1495 -20.052 3.16509 0 -1e-06 -0.00039</pose>
        <scale>1 1 1</scale>
        <link name='link'>
          <pose frame=''>23.1495 -20.052 3.16509 0 -1e-06 -0.00039</pose>
          <velocity>0 0 0 0 -0 0</velocity>
          <acceleration>1.13516 -2.91123 8.60282 -2.7355 0.27473 -2.68997</acceleration>
          <wrench>1.13516 -2.91123 8.60282 0 -0 0</wrench>
        </link>
      </model>
      <model name='unit_box_2_clone_5_clone'>
        <pose frame=''>38.5243 -9.20646 3.16509 -0 -1e-06 -0.000322</pose>
        <scale>1 1 1</scale>
        <link name='link'>
          <pose frame=''>38.5243 -9.20646 3.16509 -0 -1e-06 -0.000322</pose>
          <velocity>0 0 0 0 -0 0</velocity>
          <acceleration>1.13712 2.91188 8.6006 2.73693 0.276174 2.68847</acceleration>
          <wrench>1.13712 2.91188 8.6006 0 -0 0</wrench>
        </link>
      </model>
      <model name='unit_box_2_clone_5_clone_0'>
        <pose frame=''>41.6015 7.05091 3.16509 0 -1e-06 -0.000204</pose>
        <scale>1 1 1</scale>
        <link name='link'>
          <pose frame=''>41.6015 7.05091 3.16509 0 -1e-06 -0.000204</pose>
          <velocity>0 0 0 0 -0 0</velocity>
          <acceleration>1.1368 2.91178 8.60097 2.73669 0.275934 2.68872</acceleration>
          <wrench>1.1368 2.91178 8.60097 0 -0 0</wrench>
        </link>
      </model>
      <model name='unit_box_2_clone_5_clone_1'>
        <pose frame=''>34.4969 -28.3741 3.16509 0 1e-06 -0.00038</pose>
        <scale>1 1 1</scale>
        <link name='link'>
          <pose frame=''>34.4969 -28.3741 3.16509 0 1e-06 -0.00038</pose>
          <velocity>0 0 0 0 -0 0</velocity>
          <acceleration>-1.13519 2.91124 8.60279 2.73552 -0.27475 -2.68995</acceleration>
          <wrench>-1.13519 2.91124 8.60279 0 -0 0</wrench>
        </link>
      </model>
      <model name='unit_box_2_clone_5_clone_2'>
        <pose frame=''>-5.29989 -36.2773 3.16509 -0 -1e-06 8e-06</pose>
        <scale>1 1 1</scale>
        <link name='link'>
          <pose frame=''>-5.29989 -36.2773 3.16509 -0 -1e-06 8e-06</pose>
          <velocity>0 0 0 0 -0 0</velocity>
          <acceleration>1.13621 2.91158 8.60163 2.73627 0.275505 2.68917</acceleration>
          <wrench>1.13621 2.91158 8.60163 0 -0 0</wrench>
        </link>
      </model>
      <model name='unit_box_2_clone_5_clone_3'>
        <pose frame=''>-13.5113 25.4024 3.16509 -0 -1e-06 -0.000623</pose>
        <scale>1 1 1</scale>
        <link name='link'>
          <pose frame=''>-13.5113 25.4024 3.16509 -0 -1e-06 -0.000623</pose>
          <velocity>0 0 0 0 -0 0</velocity>
          <acceleration>1.13451 -2.91102 8.60355 -2.73503 0.274257 -2.69047</acceleration>
          <wrench>1.13451 -2.91102 8.60355 0 -0 0</wrench>
        </link>
      </model>
      <model name='unit_box_2_clone_5_clone_4'>
        <pose frame=''>27.7826 25.4091 3.16509 -0 1e-06 0.000248</pose>
        <scale>1 1 1</scale>
        <link name='link'>
          <pose frame=''>27.7826 25.4091 3.16509 -0 1e-06 0.000248</pose>
          <velocity>0 0 0 0 -0 0</velocity>
          <acceleration>-1.13555 -2.91136 8.60238 -2.73579 -0.275018 2.68967</acceleration>
          <wrench>-1.13555 -2.91136 8.60238 0 -0 0</wrench>
        </link>
      </model>
      <model name='unit_box_clone'>
        <pose frame=''>9.76822 -14.2563 0.499995 -1e-05 -0 0</pose>
        <scale>1 1 1</scale>
        <link name='link'>
          <pose frame=''>9.76822 -14.2563 0.499995 -1e-05 -0 0</pose>
          <velocity>0 0 0 0 -0 0</velocity>
          <acceleration>0.004709 0.011055 -9.78158 -0.022108 0.009414 1e-06</acceleration>
          <wrench>0.004709 0.011055 -9.78158 0 -0 0</wrench>
        </link>
      </model>
      <model name='unit_box_clone_0'>
        <pose frame=''>31.3415 -15.5854 0.499995 1e-05 -0 0</pose>
        <scale>1 1 1</scale>
        <link name='link'>
          <pose frame=''>31.3415 -15.5854 0.499995 1e-05 -0 0</pose>
          <velocity>0 0 0 0 -0 0</velocity>
          <acceleration>0.004709 -0.011055 -9.78158 0.022108 0.009414 -1e-06</acceleration>
          <wrench>0.004709 -0.011055 -9.78158 0 -0 0</wrench>
        </link>
      </model>
      <model name='unit_box_clone_1'>
        <pose frame=''>28.3693 4.92471 0.499995 0 1e-05 0</pose>
        <scale>1 1 1</scale>
        <link name='link'>
          <pose frame=''>28.3693 4.92471 0.499995 0 1e-05 0</pose>
          <velocity>0 0 0 0 -0 0</velocity>
          <acceleration>0.010615 0.006191 -9.78231 -0.012424 0.021225 -1.8e-05</acceleration>
          <wrench>0.010615 0.006191 -9.78231 0 -0 0</wrench>
        </link>
      </model>
      <model name='unit_box_clone_2'>
        <pose frame=''>13.7163 -0.094858 0.499995 -1e-05 -0 5e-06</pose>
        <scale>1 1 1</scale>
        <link name='link'>
          <pose frame=''>13.7163 -0.094858 0.499995 -1e-05 -0 5e-06</pose>
          <velocity>0 0 0 0 -0 0</velocity>
          <acceleration>-0.004709 0.011055 -9.78158 -0.022107 -0.009414 -1e-06</acceleration>
          <wrench>-0.004709 0.011055 -9.78158 0 -0 0</wrench>
        </link>
      </model>
      <model name='unit_cylinder'>
        <pose frame=''>-4.35398 10.0664 0.499993 -3e-06 2e-06 0</pose>
        <scale>1 1 1</scale>
        <link name='link'>
          <pose frame=''>-4.35398 10.0664 0.499993 -3e-06 2e-06 0</pose>
          <velocity>0 0 0 0 -0 0</velocity>
          <acceleration>0 0 -9.8 0 -0 0</acceleration>
          <wrench>0 0 -9.8 0 -0 0</wrench>
        </link>
      </model>
      <model name='unit_cylinder_0'>
        <pose frame=''>-8.54331 -6.45791 0.499993 -3e-06 2e-06 0</pose>
        <scale>1 1 1</scale>
        <link name='link'>
          <pose frame=''>-8.54331 -6.45791 0.499993 -3e-06 2e-06 0</pose>
          <velocity>0 0 0 0 -0 0</velocity>
          <acceleration>0 0 -9.8 0 -0 0</acceleration>
          <wrench>0 0 -9.8 0 -0 0</wrench>
        </link>
      </model>
      <model name='unit_cylinder_1'>
        <pose frame=''>-17.0483 2.49024 0.499993 -3e-06 2e-06 0</pose>
        <scale>1 1 1</scale>
        <link name='link'>
          <pose frame=''>-17.0483 2.49024 0.499993 -3e-06 2e-06 0</pose>
          <velocity>0 0 0 0 -0 0</velocity>
          <acceleration>0 0 -9.8 0 -0 0</acceleration>
          <wrench>0 0 -9.8 0 -0 0</wrench>
        </link>
      </model>
      <model name='unit_cylinder_2'>
        <pose frame=''>17.552 -31.5845 2.92198 1e-06 0 -9e-05</pose>
        <scale>7.94318 7.94318 5.84397</scale>
        <link name='link'>
          <pose frame=''>17.552 -31.5845 2.92198 1e-06 0 -9e-05</pose>
          <velocity>0 0 0 0 -0 0</velocity>
          <acceleration>0 0 -9.8 0 -0 0</acceleration>
          <wrench>0 0 -9.8 0 -0 0</wrench>
        </link>
      </model>
      <model name='unit_cylinder_2_clone'>
        <pose frame=''>-12.7951 -24.9645 2.92198 0 0 -9.7e-05</pose>
        <scale>1 1 1</scale>
        <link name='link'>
          <pose frame=''>-12.7951 -24.9645 2.92198 0 0 -9.7e-05</pose>
          <velocity>0 0 0 0 -0 0</velocity>
          <acceleration>0.381901 0.635641 -9.03028 -0.477269 0.097197 -0.13146</acceleration>
          <wrench>0.381901 0.635641 -9.03028 0 -0 0</wrench>
        </link>
      </model>
      <model name='unit_cylinder_2_clone_0'>
        <pose frame=''>-27.8323 24.834 2.92198 0 0 -9.7e-05</pose>
        <scale>1 1 1</scale>
        <link name='link'>
          <pose frame=''>-27.8323 24.834 2.92198 0 0 -9.7e-05</pose>
          <velocity>0 0 0 0 -0 0</velocity>
          <acceleration>0.381901 0.635641 -9.03028 -0.477269 0.097197 -0.13146</acceleration>
          <wrench>0.381901 0.635641 -9.03028 0 -0 0</wrench>
        </link>
      </model>
      <model name='unit_cylinder_2_clone_1'>
        <pose frame=''>28.3724 12.0602 2.92198 0 0 -9.7e-05</pose>
        <scale>1 1 1</scale>
        <link name='link'>
          <pose frame=''>28.3724 12.0602 2.92198 0 0 -9.7e-05</pose>
          <velocity>0 0 0 0 -0 0</velocity>
          <acceleration>0.381901 0.635641 -9.03028 -0.477269 0.097197 -0.13146</acceleration>
          <wrench>0.381901 0.635641 -9.03028 0 -0 0</wrench>
        </link>
      </model>
      <light name='sun'>
        <pose frame=''>0 0 10 0 -0 0</pose>
      </light>
    </state>
    <model name='unit_box'>
      <pose frame=''>3 -4.49894 0.5 0 -0 0</pose>
      <link name='link'>
        <inertial>
          <mass>1</mass>
          <inertia>
            <ixx>0.166667</ixx>
            <ixy>0</ixy>
            <ixz>0</ixz>
            <iyy>0.166667</iyy>
            <iyz>0</iyz>
            <izz>0.166667</izz>
          </inertia>
        </inertial>
        <collision name='collision'>
          <geometry>
            <box>
              <size>1 1 1</size>
            </box>
          </geometry>
          <max_contacts>10</max_contacts>
          <surface>
            <contact>
              <ode/>
            </contact>
            <bounce/>
            <friction>
              <torsional>
                <ode/>
              </torsional>
              <ode/>
            </friction>
          </surface>
        </collision>
        <visual name='visual'>
          <geometry>
            <box>
              <size>1 1 1</size>
            </box>
          </geometry>
          <material>
            <script>
              <name>Gazebo/Grey</name>
              <uri>file://media/materials/scripts/gazebo.material</uri>
            </script>
          </material>
        </visual>
        <self_collide>0</self_collide>
        <enable_wind>0</enable_wind>
        <kinematic>0</kinematic>
      </link>
    </model>
    <model name='unit_box_0'>
      <pose frame=''>-4.99199 1.77228 0.5 0 -0 0</pose>
      <link name='link'>
        <inertial>
          <mass>1</mass>
          <inertia>
            <ixx>0.166667</ixx>
            <ixy>0</ixy>
            <ixz>0</ixz>
            <iyy>0.166667</iyy>
            <iyz>0</iyz>
            <izz>0.166667</izz>
          </inertia>
        </inertial>
        <collision name='collision'>
          <geometry>
            <box>
              <size>1 1 1</size>
            </box>
          </geometry>
          <max_contacts>10</max_contacts>
          <surface>
            <contact>
              <ode/>
            </contact>
            <bounce/>
            <friction>
              <torsional>
                <ode/>
              </torsional>
              <ode/>
            </friction>
          </surface>
        </collision>
        <visual name='visual'>
          <geometry>
            <box>
              <size>1 1 1</size>
            </box>
          </geometry>
          <material>
            <script>
              <name>Gazebo/Grey</name>
              <uri>file://media/materials/scripts/gazebo.material</uri>
            </script>
          </material>
        </visual>
        <self_collide>0</self_collide>
        <enable_wind>0</enable_wind>
        <kinematic>0</kinematic>
      </link>
    </model>
    <model name='unit_box_1'>
      <pose frame=''>5.82101 7.27451 0.5 0 -0 0</pose>
      <link name='link'>
        <inertial>
          <mass>1</mass>
          <inertia>
            <ixx>0.166667</ixx>
            <ixy>0</ixy>
            <ixz>0</ixz>
            <iyy>0.166667</iyy>
            <iyz>0</iyz>
            <izz>0.166667</izz>
          </inertia>
        </inertial>
        <collision name='collision'>
          <geometry>
            <box>
              <size>1 1 1</size>
            </box>
          </geometry>
          <max_contacts>10</max_contacts>
          <surface>
            <contact>
              <ode/>
            </contact>
            <bounce/>
            <friction>
              <torsional>
                <ode/>
              </torsional>
              <ode/>
            </friction>
          </surface>
        </collision>
        <visual name='visual'>
          <geometry>
            <box>
              <size>1 1 1</size>
            </box>
          </geometry>
          <material>
            <script>
              <name>Gazebo/Grey</name>
              <uri>file://media/materials/scripts/gazebo.material</uri>
            </script>
          </material>
        </visual>
        <self_collide>0</self_collide>
        <enable_wind>0</enable_wind>
        <kinematic>0</kinematic>
      </link>
    </model>
    <model name='unit_cylinder'>
      <pose frame=''>-4.35397 10.0664 0.5 0 -0 0</pose>
      <link name='link'>
        <inertial>
          <mass>1</mass>
          <inertia>
            <ixx>0.145833</ixx>
            <ixy>0</ixy>
            <ixz>0</ixz>
            <iyy>0.145833</iyy>
            <iyz>0</iyz>
            <izz>0.125</izz>
          </inertia>
        </inertial>
        <collision name='collision'>
          <geometry>
            <cylinder>
              <radius>0.5</radius>
              <length>1</length>
            </cylinder>
          </geometry>
          <max_contacts>10</max_contacts>
          <surface>
            <contact>
              <ode/>
            </contact>
            <bounce/>
            <friction>
              <torsional>
                <ode/>
              </torsional>
              <ode/>
            </friction>
          </surface>
        </collision>
        <visual name='visual'>
          <geometry>
            <cylinder>
              <radius>0.5</radius>
              <length>1</length>
            </cylinder>
          </geometry>
          <material>
            <script>
              <name>Gazebo/Grey</name>
              <uri>file://media/materials/scripts/gazebo.material</uri>
            </script>
          </material>
        </visual>
        <self_collide>0</self_collide>
        <enable_wind>0</enable_wind>
        <kinematic>0</kinematic>
      </link>
    </model>
    <model name='unit_cylinder_0'>
      <pose frame=''>-8.5433 -6.4579 0.5 0 -0 0</pose>
      <link name='link'>
        <inertial>
          <mass>1</mass>
          <inertia>
            <ixx>0.145833</ixx>
            <ixy>0</ixy>
            <ixz>0</ixz>
            <iyy>0.145833</iyy>
            <iyz>0</iyz>
            <izz>0.125</izz>
          </inertia>
        </inertial>
        <collision name='collision'>
          <geometry>
            <cylinder>
              <radius>0.5</radius>
              <length>1</length>
            </cylinder>
          </geometry>
          <max_contacts>10</max_contacts>
          <surface>
            <contact>
              <ode/>
            </contact>
            <bounce/>
            <friction>
              <torsional>
                <ode/>
              </torsional>
              <ode/>
            </friction>
          </surface>
        </collision>
        <visual name='visual'>
          <geometry>
            <cylinder>
              <radius>0.5</radius>
              <length>1</length>
            </cylinder>
          </geometry>
          <material>
            <script>
              <name>Gazebo/Grey</name>
              <uri>file://media/materials/scripts/gazebo.material</uri>
            </script>
          </material>
        </visual>
        <self_collide>0</self_collide>
        <enable_wind>0</enable_wind>
        <kinematic>0</kinematic>
      </link>
    </model>
    <model name='unit_cylinder_1'>
      <pose frame=''>-17.0483 2.49025 0.5 0 -0 0</pose>
      <link name='link'>
        <inertial>
          <mass>1</mass>
          <inertia>
            <ixx>0.145833</ixx>
            <ixy>0</ixy>
            <ixz>0</ixz>
            <iyy>0.145833</iyy>
            <iyz>0</iyz>
            <izz>0.125</izz>
          </inertia>
        </inertial>
        <collision name='collision'>
          <geometry>
            <cylinder>
              <radius>0.5</radius>
              <length>1</length>
            </cylinder>
          </geometry>
          <max_contacts>10</max_contacts>
          <surface>
            <contact>
              <ode/>
            </contact>
            <bounce/>
            <friction>
              <torsional>
                <ode/>
              </torsional>
              <ode/>
            </friction>
          </surface>
        </collision>
        <visual name='visual'>
          <geometry>
            <cylinder>
              <radius>0.5</radius>
              <length>1</length>
            </cylinder>
          </geometry>
          <material>
            <script>
              <name>Gazebo/Grey</name>
              <uri>file://media/materials/scripts/gazebo.material</uri>
            </script>
          </material>
        </visual>
        <self_collide>0</self_collide>
        <enable_wind>0</enable_wind>
        <kinematic>0</kinematic>
      </link>
    </model>
    <model name='unit_box_2_clone'>
      <pose frame=''>-10.4112 -15.4302 1.56096 0 -0 0</pose>
      <link name='link'>
        <inertial>
          <mass>1</mass>
          <inertia>
            <ixx>0.166667</ixx>
            <ixy>0</ixy>
            <ixz>0</ixz>
            <iyy>0.166667</iyy>
            <iyz>0</iyz>
            <izz>0.166667</izz>
          </inertia>
        </inertial>
        <collision name='collision'>
          <geometry>
            <box>
              <size>3.93004 4.88437 3.08535</size>
            </box>
          </geometry>
          <max_contacts>10</max_contacts>
          <surface>
            <contact>
              <ode/>
            </contact>
            <bounce/>
            <friction>
              <torsional>
                <ode/>
              </torsional>
              <ode/>
            </friction>
          </surface>
        </collision>
        <visual name='visual'>
          <geometry>
            <box>
              <size>3.93004 4.88437 3.08535</size>
            </box>
          </geometry>
          <material>
            <script>
              <name>Gazebo/Grey</name>
              <uri>file://media/materials/scripts/gazebo.material</uri>
            </script>
          </material>
        </visual>
        <self_collide>0</self_collide>
        <enable_wind>0</enable_wind>
        <kinematic>0</kinematic>
      </link>
    </model>
    <model name='unit_box_2_clone_0'>
      <pose frame=''>-13.9419 8.84197 1.56096 0 -0 0</pose>
      <link name='link'>
        <inertial>
          <mass>1</mass>
          <inertia>
            <ixx>0.166667</ixx>
            <ixy>0</ixy>
            <ixz>0</ixz>
            <iyy>0.166667</iyy>
            <iyz>0</iyz>
            <izz>0.166667</izz>
          </inertia>
        </inertial>
        <collision name='collision'>
          <geometry>
            <box>
              <size>3.93004 4.88437 3.08535</size>
            </box>
          </geometry>
          <max_contacts>10</max_contacts>
          <surface>
            <contact>
              <ode/>
            </contact>
            <bounce/>
            <friction>
              <torsional>
                <ode/>
              </torsional>
              <ode/>
            </friction>
          </surface>
        </collision>
        <visual name='visual'>
          <geometry>
            <box>
              <size>3.93004 4.88437 3.08535</size>
            </box>
          </geometry>
          <material>
            <script>
              <name>Gazebo/Grey</name>
              <uri>file://media/materials/scripts/gazebo.material</uri>
            </script>
          </material>
        </visual>
        <self_collide>0</self_collide>
        <enable_wind>0</enable_wind>
        <kinematic>0</kinematic>
      </link>
    </model>
    <model name='unit_box_2_clone_1'>
      <pose frame=''>3.28992 -26.3429 1.56096 0 -0 0</pose>
      <link name='link'>
        <inertial>
          <mass>1</mass>
          <inertia>
            <ixx>0.166667</ixx>
            <ixy>0</ixy>
            <ixz>0</ixz>
            <iyy>0.166667</iyy>
            <iyz>0</iyz>
            <izz>0.166667</izz>
          </inertia>
        </inertial>
        <collision name='collision'>
          <geometry>
            <box>
              <size>3.93004 4.88437 3.08535</size>
            </box>
          </geometry>
          <max_contacts>10</max_contacts>
          <surface>
            <contact>
              <ode/>
            </contact>
            <bounce/>
            <friction>
              <torsional>
                <ode/>
              </torsional>
              <ode/>
            </friction>
          </surface>
        </collision>
        <visual name='visual'>
          <geometry>
            <box>
              <size>3.93004 4.88437 3.08535</size>
            </box>
          </geometry>
          <material>
            <script>
              <name>Gazebo/Grey</name>
              <uri>file://media/materials/scripts/gazebo.material</uri>
            </script>
          </material>
        </visual>
        <self_collide>0</self_collide>
        <enable_wind>0</enable_wind>
        <kinematic>0</kinematic>
      </link>
    </model>
    <model name='unit_box_2_clone_2'>
      <pose frame=''>13.3079 7.61794 1.56096 0 -0 0</pose>
      <link name='link'>
        <inertial>
          <mass>1</mass>
          <inertia>
            <ixx>0.166667</ixx>
            <ixy>0</ixy>
            <ixz>0</ixz>
            <iyy>0.166667</iyy>
            <iyz>0</iyz>
            <izz>0.166667</izz>
          </inertia>
        </inertial>
        <collision name='collision'>
          <geometry>
            <box>
              <size>3.93004 4.88437 3.08535</size>
            </box>
          </geometry>
          <max_contacts>10</max_contacts>
          <surface>
            <contact>
              <ode/>
            </contact>
            <bounce/>
            <friction>
              <torsional>
                <ode/>
              </torsional>
              <ode/>
            </friction>
          </surface>
        </collision>
        <visual name='visual'>
          <geometry>
            <box>
              <size>3.93004 4.88437 3.08535</size>
            </box>
          </geometry>
          <material>
            <script>
              <name>Gazebo/Grey</name>
              <uri>file://media/materials/scripts/gazebo.material</uri>
            </script>
          </material>
        </visual>
        <self_collide>0</self_collide>
        <enable_wind>0</enable_wind>
        <kinematic>0</kinematic>
      </link>
    </model>
    <model name='unit_box_2_clone_3'>
      <pose frame=''>-22.5002 -3.53895 3.36213 0 -0 0</pose>
      <link name='link'>
        <inertial>
          <mass>1</mass>
          <inertia>
            <ixx>0.166667</ixx>
            <ixy>0</ixy>
            <ixz>0</ixz>
            <iyy>0.166667</iyy>
            <iyz>0</iyz>
            <izz>0.166667</izz>
          </inertia>
        </inertial>
        <collision name='collision'>
          <geometry>
            <box>
              <size>7.13047 6.46568 6.33019</size>
            </box>
          </geometry>
          <max_contacts>10</max_contacts>
          <surface>
            <contact>
              <ode/>
            </contact>
            <bounce/>
            <friction>
              <torsional>
                <ode/>
              </torsional>
              <ode/>
            </friction>
          </surface>
        </collision>
        <visual name='visual'>
          <geometry>
            <box>
              <size>7.13047 6.46568 6.33019</size>
            </box>
          </geometry>
          <material>
            <script>
              <name>Gazebo/Grey</name>
              <uri>file://media/materials/scripts/gazebo.material</uri>
            </script>
          </material>
        </visual>
        <self_collide>0</self_collide>
        <enable_wind>0</enable_wind>
        <kinematic>0</kinematic>
      </link>
    </model>
    <model name='unit_box_2_clone_4'>
      <pose frame=''>4.28851 21.3891 3.36213 0 -0 0</pose>
      <link name='link'>
        <inertial>
          <mass>1</mass>
          <inertia>
            <ixx>0.166667</ixx>
            <ixy>0</ixy>
            <ixz>0</ixz>
            <iyy>0.166667</iyy>
            <iyz>0</iyz>
            <izz>0.166667</izz>
          </inertia>
        </inertial>
        <collision name='collision'>
          <geometry>
            <box>
              <size>7.13047 6.46568 6.33019</size>
            </box>
          </geometry>
          <max_contacts>10</max_contacts>
          <surface>
            <contact>
              <ode/>
            </contact>
            <bounce/>
            <friction>
              <torsional>
                <ode/>
              </torsional>
              <ode/>
            </friction>
          </surface>
        </collision>
        <visual name='visual'>
          <geometry>
            <box>
              <size>7.13047 6.46568 6.33019</size>
            </box>
          </geometry>
          <material>
            <script>
              <name>Gazebo/Grey</name>
              <uri>file://media/materials/scripts/gazebo.material</uri>
            </script>
          </material>
        </visual>
        <self_collide>0</self_collide>
        <enable_wind>0</enable_wind>
        <kinematic>0</kinematic>
      </link>
    </model>
    <model name='unit_box_2_clone_5'>
      <pose frame=''>23.1453 -20.0518 3.36213 0 -0 0</pose>
      <link name='link'>
        <inertial>
          <mass>1</mass>
          <inertia>
            <ixx>0.166667</ixx>
            <ixy>0</ixy>
            <ixz>0</ixz>
            <iyy>0.166667</iyy>
            <iyz>0</iyz>
            <izz>0.166667</izz>
          </inertia>
        </inertial>
        <collision name='collision'>
          <geometry>
            <box>
              <size>7.13047 6.46568 6.33019</size>
            </box>
          </geometry>
          <max_contacts>10</max_contacts>
          <surface>
            <contact>
              <ode/>
            </contact>
            <bounce/>
            <friction>
              <torsional>
                <ode/>
              </torsional>
              <ode/>
            </friction>
          </surface>
        </collision>
        <visual name='visual'>
          <geometry>
            <box>
              <size>7.13047 6.46568 6.33019</size>
            </box>
          </geometry>
          <material>
            <script>
              <name>Gazebo/Grey</name>
              <uri>file://media/materials/scripts/gazebo.material</uri>
            </script>
          </material>
        </visual>
        <self_collide>0</self_collide>
        <enable_wind>0</enable_wind>
        <kinematic>0</kinematic>
      </link>
    </model>
    <model name='unit_cylinder_2'>
      <pose frame=''>-0.966255 -17.8918 0.5 0 -0 0</pose>
      <link name='link'>
        <inertial>
          <mass>1</mass>
          <inertia>
            <ixx>0.145833</ixx>
            <ixy>0</ixy>
            <ixz>0</ixz>
            <iyy>0.145833</iyy>
            <iyz>0</iyz>
            <izz>0.125</izz>
          </inertia>
        </inertial>
        <collision name='collision'>
          <geometry>
            <cylinder>
              <radius>0.5</radius>
              <length>0.999998</length>
            </cylinder>
          </geometry>
          <max_contacts>10</max_contacts>
          <surface>
            <contact>
              <ode/>
            </contact>
            <bounce/>
            <friction>
              <torsional>
                <ode/>
              </torsional>
              <ode/>
            </friction>
          </surface>
        </collision>
        <visual name='visual'>
          <geometry>
            <cylinder>
              <radius>0.5</radius>
              <length>0.999998</length>
            </cylinder>
          </geometry>
          <material>
            <script>
              <name>Gazebo/Grey</name>
              <uri>file://media/materials/scripts/gazebo.material</uri>
            </script>
          </material>
        </visual>
        <self_collide>0</self_collide>
        <enable_wind>0</enable_wind>
        <kinematic>0</kinematic>
      </link>
    </model>
    <model name='unit_cylinder_2_clone'>
      <pose frame=''>-12.7989 -24.9556 3.36928 0 -0 0</pose>
      <link name='link'>
        <inertial>
          <mass>1</mass>
          <inertia>
            <ixx>0.145833</ixx>
            <ixy>0</ixy>
            <ixz>0</ixz>
            <iyy>0.145833</iyy>
            <iyz>0</iyz>
            <izz>0.125</izz>
          </inertia>
        </inertial>
        <collision name='collision'>
          <geometry>
            <cylinder>
              <radius>3.97159</radius>
              <length>5.84397</length>
            </cylinder>
          </geometry>
          <max_contacts>10</max_contacts>
          <surface>
            <contact>
              <ode/>
            </contact>
            <bounce/>
            <friction>
              <torsional>
                <ode/>
              </torsional>
              <ode/>
            </friction>
          </surface>
        </collision>
        <visual name='visual'>
          <geometry>
            <cylinder>
              <radius>3.97159</radius>
              <length>5.84397</length>
            </cylinder>
          </geometry>
          <material>
            <script>
              <name>Gazebo/Grey</name>
              <uri>file://media/materials/scripts/gazebo.material</uri>
            </script>
          </material>
        </visual>
        <self_collide>0</self_collide>
        <enable_wind>0</enable_wind>
        <kinematic>0</kinematic>
      </link>
    </model>
    <model name='unit_cylinder_2_clone_0'>
      <pose frame=''>-27.8361 24.8429 3.36928 0 -0 0</pose>
      <link name='link'>
        <inertial>
          <mass>1</mass>
          <inertia>
            <ixx>0.145833</ixx>
            <ixy>0</ixy>
            <ixz>0</ixz>
            <iyy>0.145833</iyy>
            <iyz>0</iyz>
            <izz>0.125</izz>
          </inertia>
        </inertial>
        <collision name='collision'>
          <geometry>
            <cylinder>
              <radius>3.97159</radius>
              <length>5.84397</length>
            </cylinder>
          </geometry>
          <max_contacts>10</max_contacts>
          <surface>
            <contact>
              <ode/>
            </contact>
            <bounce/>
            <friction>
              <torsional>
                <ode/>
              </torsional>
              <ode/>
            </friction>
          </surface>
        </collision>
        <visual name='visual'>
          <geometry>
            <cylinder>
              <radius>3.97159</radius>
              <length>5.84397</length>
            </cylinder>
          </geometry>
          <material>
            <script>
              <name>Gazebo/Grey</name>
              <uri>file://media/materials/scripts/gazebo.material</uri>
            </script>
          </material>
        </visual>
        <self_collide>0</self_collide>
        <enable_wind>0</enable_wind>
        <kinematic>0</kinematic>
      </link>
    </model>
    <model name='unit_cylinder_2_clone_1'>
      <pose frame=''>28.3686 12.0691 3.36928 0 -0 0</pose>
      <link name='link'>
        <inertial>
          <mass>1</mass>
          <inertia>
            <ixx>0.145833</ixx>
            <ixy>0</ixy>
            <ixz>0</ixz>
            <iyy>0.145833</iyy>
            <iyz>0</iyz>
            <izz>0.125</izz>
          </inertia>
        </inertial>
        <collision name='collision'>
          <geometry>
            <cylinder>
              <radius>3.97159</radius>
              <length>5.84397</length>
            </cylinder>
          </geometry>
          <max_contacts>10</max_contacts>
          <surface>
            <contact>
              <ode/>
            </contact>
            <bounce/>
            <friction>
              <torsional>
                <ode/>
              </torsional>
              <ode/>
            </friction>
          </surface>
        </collision>
        <visual name='visual'>
          <geometry>
            <cylinder>
              <radius>3.97159</radius>
              <length>5.84397</length>
            </cylinder>
          </geometry>
          <material>
            <script>
              <name>Gazebo/Grey</name>
              <uri>file://media/materials/scripts/gazebo.material</uri>
            </script>
          </material>
        </visual>
        <self_collide>0</self_collide>
        <enable_wind>0</enable_wind>
        <kinematic>0</kinematic>
      </link>
    </model>
    <model name='unit_box_2_clone_5_clone'>
      <pose frame=''>38.5241 -9.20644 3.16509 0 1e-06 9.4e-05</pose>
      <link name='link'>
        <inertial>
          <mass>1</mass>
          <inertia>
            <ixx>0.166667</ixx>
            <ixy>0</ixy>
            <ixz>0</ixz>
            <iyy>0.166667</iyy>
            <iyz>0</iyz>
            <izz>0.166667</izz>
          </inertia>
        </inertial>
        <collision name='collision'>
          <geometry>
            <box>
              <size>7.13047 6.46568 6.33019</size>
            </box>
          </geometry>
          <max_contacts>10</max_contacts>
          <surface>
            <contact>
              <ode/>
            </contact>
            <bounce/>
            <friction>
              <torsional>
                <ode/>
              </torsional>
              <ode/>
            </friction>
          </surface>
        </collision>
        <visual name='visual'>
          <geometry>
            <box>
              <size>7.13047 6.46568 6.33019</size>
            </box>
          </geometry>
          <material>
            <script>
              <name>Gazebo/Grey</name>
              <uri>file://media/materials/scripts/gazebo.material</uri>
            </script>
          </material>
        </visual>
        <self_collide>0</self_collide>
        <enable_wind>0</enable_wind>
        <kinematic>0</kinematic>
      </link>
    </model>
    <model name='unit_box_2_clone_5_clone_0'>
      <pose frame=''>41.6013 7.05093 3.16509 0 1e-06 9.4e-05</pose>
      <link name='link'>
        <inertial>
          <mass>1</mass>
          <inertia>
            <ixx>0.166667</ixx>
            <ixy>0</ixy>
            <ixz>0</ixz>
            <iyy>0.166667</iyy>
            <iyz>0</iyz>
            <izz>0.166667</izz>
          </inertia>
        </inertial>
        <collision name='collision'>
          <geometry>
            <box>
              <size>7.13047 6.46568 6.33019</size>
            </box>
          </geometry>
          <max_contacts>10</max_contacts>
          <surface>
            <contact>
              <ode/>
            </contact>
            <bounce/>
            <friction>
              <torsional>
                <ode/>
              </torsional>
              <ode/>
            </friction>
          </surface>
        </collision>
        <visual name='visual'>
          <geometry>
            <box>
              <size>7.13047 6.46568 6.33019</size>
            </box>
          </geometry>
          <material>
            <script>
              <name>Gazebo/Grey</name>
              <uri>file://media/materials/scripts/gazebo.material</uri>
            </script>
          </material>
        </visual>
        <self_collide>0</self_collide>
        <enable_wind>0</enable_wind>
        <kinematic>0</kinematic>
      </link>
    </model>
    <model name='unit_box_2_clone_5_clone_1'>
      <pose frame=''>34.497 -28.3741 3.16509 0 1e-06 9.4e-05</pose>
      <link name='link'>
        <inertial>
          <mass>1</mass>
          <inertia>
            <ixx>0.166667</ixx>
            <ixy>0</ixy>
            <ixz>0</ixz>
            <iyy>0.166667</iyy>
            <iyz>0</iyz>
            <izz>0.166667</izz>
          </inertia>
        </inertial>
        <collision name='collision'>
          <geometry>
            <box>
              <size>7.13047 6.46568 6.33019</size>
            </box>
          </geometry>
          <max_contacts>10</max_contacts>
          <surface>
            <contact>
              <ode/>
            </contact>
            <bounce/>
            <friction>
              <torsional>
                <ode/>
              </torsional>
              <ode/>
            </friction>
          </surface>
        </collision>
        <visual name='visual'>
          <geometry>
            <box>
              <size>7.13047 6.46568 6.33019</size>
            </box>
          </geometry>
          <material>
            <script>
              <name>Gazebo/Grey</name>
              <uri>file://media/materials/scripts/gazebo.material</uri>
            </script>
          </material>
        </visual>
        <self_collide>0</self_collide>
        <enable_wind>0</enable_wind>
        <kinematic>0</kinematic>
      </link>
    </model>
    <model name='unit_box_2_clone_5_clone_2'>
      <pose frame=''>-5.3001 -36.2773 3.16509 0 1e-06 9.4e-05</pose>
      <link name='link'>
        <inertial>
          <mass>1</mass>
          <inertia>
            <ixx>0.166667</ixx>
            <ixy>0</ixy>
            <ixz>0</ixz>
            <iyy>0.166667</iyy>
            <iyz>0</iyz>
            <izz>0.166667</izz>
          </inertia>
        </inertial>
        <collision name='collision'>
          <geometry>
            <box>
              <size>7.13047 6.46568 6.33019</size>
            </box>
          </geometry>
          <max_contacts>10</max_contacts>
          <surface>
            <contact>
              <ode/>
            </contact>
            <bounce/>
            <friction>
              <torsional>
                <ode/>
              </torsional>
              <ode/>
            </friction>
          </surface>
        </collision>
        <visual name='visual'>
          <geometry>
            <box>
              <size>7.13047 6.46568 6.33019</size>
            </box>
          </geometry>
          <material>
            <script>
              <name>Gazebo/Grey</name>
              <uri>file://media/materials/scripts/gazebo.material</uri>
            </script>
          </material>
        </visual>
        <self_collide>0</self_collide>
        <enable_wind>0</enable_wind>
        <kinematic>0</kinematic>
      </link>
    </model>
    <model name='unit_box_2_clone_5_clone_3'>
      <pose frame=''>-13.5115 25.4024 3.16509 0 1e-06 9.4e-05</pose>
      <link name='link'>
        <inertial>
          <mass>1</mass>
          <inertia>
            <ixx>0.166667</ixx>
            <ixy>0</ixy>
            <ixz>0</ixz>
            <iyy>0.166667</iyy>
            <iyz>0</iyz>
            <izz>0.166667</izz>
          </inertia>
        </inertial>
        <collision name='collision'>
          <geometry>
            <box>
              <size>7.13047 6.46568 6.33019</size>
            </box>
          </geometry>
          <max_contacts>10</max_contacts>
          <surface>
            <contact>
              <ode/>
            </contact>
            <bounce/>
            <friction>
              <torsional>
                <ode/>
              </torsional>
              <ode/>
            </friction>
          </surface>
        </collision>
        <visual name='visual'>
          <geometry>
            <box>
              <size>7.13047 6.46568 6.33019</size>
            </box>
          </geometry>
          <material>
            <script>
              <name>Gazebo/Grey</name>
              <uri>file://media/materials/scripts/gazebo.material</uri>
            </script>
          </material>
        </visual>
        <self_collide>0</self_collide>
        <enable_wind>0</enable_wind>
        <kinematic>0</kinematic>
      </link>
    </model>
    <model name='unit_box_2_clone_5_clone_4'>
      <pose frame=''>27.7828 25.4091 3.16509 0 1e-06 9.4e-05</pose>
      <link name='link'>
        <inertial>
          <mass>1</mass>
          <inertia>
            <ixx>0.166667</ixx>
            <ixy>0</ixy>
            <ixz>0</ixz>
            <iyy>0.166667</iyy>
            <iyz>0</iyz>
            <izz>0.166667</izz>
          </inertia>
        </inertial>
        <collision name='collision'>
          <geometry>
            <box>
              <size>7.13047 6.46568 6.33019</size>
            </box>
          </geometry>
          <max_contacts>10</max_contacts>
          <surface>
            <contact>
              <ode/>
            </contact>
            <bounce/>
            <friction>
              <torsional>
                <ode/>
              </torsional>
              <ode/>
            </friction>
          </surface>
        </collision>
        <visual name='visual'>
          <geometry>
            <box>
              <size>7.13047 6.46568 6.33019</size>
            </box>
          </geometry>
          <material>
            <script>
              <name>Gazebo/Grey</name>
              <uri>file://media/materials/scripts/gazebo.material</uri>
            </script>
          </material>
        </visual>
        <self_collide>0</self_collide>
        <enable_wind>0</enable_wind>
        <kinematic>0</kinematic>
      </link>
    </model>
    <model name='unit_box_clone'>
      <pose frame=''>6.58789 -17.7023 0.5 0 -0 0</pose>
      <link name='link'>
        <inertial>
          <mass>1</mass>
          <inertia>
            <ixx>0.166667</ixx>
            <ixy>0</ixy>
            <ixz>0</ixz>
            <iyy>0.166667</iyy>
            <iyz>0</iyz>
            <izz>0.166667</izz>
          </inertia>
        </inertial>
        <collision name='collision'>
          <geometry>
            <box>
              <size>1 1 1</size>
            </box>
          </geometry>
          <max_contacts>10</max_contacts>
          <surface>
            <contact>
              <ode/>
            </contact>
            <bounce/>
            <friction>
              <torsional>
                <ode/>
              </torsional>
              <ode/>
            </friction>
          </surface>
        </collision>
        <visual name='visual'>
          <geometry>
            <box>
              <size>1 1 1</size>
            </box>
          </geometry>
          <material>
            <script>
              <name>Gazebo/Grey</name>
              <uri>file://media/materials/scripts/gazebo.material</uri>
            </script>
          </material>
        </visual>
        <self_collide>0</self_collide>
        <enable_wind>0</enable_wind>
        <kinematic>0</kinematic>
      </link>
    </model>
    <model name='unit_box_clone_0'>
      <pose frame=''>31.3415 -15.5854 0.5 0 -0 0</pose>
      <link name='link'>
        <inertial>
          <mass>1</mass>
          <inertia>
            <ixx>0.166667</ixx>
            <ixy>0</ixy>
            <ixz>0</ixz>
            <iyy>0.166667</iyy>
            <iyz>0</iyz>
            <izz>0.166667</izz>
          </inertia>
        </inertial>
        <collision name='collision'>
          <geometry>
            <box>
              <size>1 1 1</size>
            </box>
          </geometry>
          <max_contacts>10</max_contacts>
          <surface>
            <contact>
              <ode/>
            </contact>
            <bounce/>
            <friction>
              <torsional>
                <ode/>
              </torsional>
              <ode/>
            </friction>
          </surface>
        </collision>
        <visual name='visual'>
          <geometry>
            <box>
              <size>1 1 1</size>
            </box>
          </geometry>
          <material>
            <script>
              <name>Gazebo/Grey</name>
              <uri>file://media/materials/scripts/gazebo.material</uri>
            </script>
          </material>
        </visual>
        <self_collide>0</self_collide>
        <enable_wind>0</enable_wind>
        <kinematic>0</kinematic>
      </link>
    </model>
    <model name='unit_box_clone_1'>
      <pose frame=''>28.3693 4.92472 0.5 0 -0 0</pose>
      <link name='link'>
        <inertial>
          <mass>1</mass>
          <inertia>
            <ixx>0.166667</ixx>
            <ixy>0</ixy>
            <ixz>0</ixz>
            <iyy>0.166667</iyy>
            <iyz>0</iyz>
            <izz>0.166667</izz>
          </inertia>
        </inertial>
        <collision name='collision'>
          <geometry>
            <box>
              <size>1 1 1</size>
            </box>
          </geometry>
          <max_contacts>10</max_contacts>
          <surface>
            <contact>
              <ode/>
            </contact>
            <bounce/>
            <friction>
              <torsional>
                <ode/>
              </torsional>
              <ode/>
            </friction>
          </surface>
        </collision>
        <visual name='visual'>
          <geometry>
            <box>
              <size>1 1 1</size>
            </box>
          </geometry>
          <material>
            <script>
              <name>Gazebo/Grey</name>
              <uri>file://media/materials/scripts/gazebo.material</uri>
            </script>
          </material>
        </visual>
        <self_collide>0</self_collide>
        <enable_wind>0</enable_wind>
        <kinematic>0</kinematic>
      </link>
    </model>
    <model name='unit_box_clone_2'>
      <pose frame=''>13.7163 -3.03531 0.499995 -1e-05 0 0</pose>
      <link name='link'>
        <inertial>
          <mass>1</mass>
          <inertia>
            <ixx>0.166667</ixx>
            <ixy>0</ixy>
            <ixz>0</ixz>
            <iyy>0.166667</iyy>
            <iyz>0</iyz>
            <izz>0.166667</izz>
          </inertia>
        </inertial>
        <collision name='collision'>
          <geometry>
            <box>
              <size>1 1 1</size>
            </box>
          </geometry>
          <max_contacts>10</max_contacts>
          <surface>
            <contact>
              <ode/>
            </contact>
            <bounce/>
            <friction>
              <torsional>
                <ode/>
              </torsional>
              <ode/>
            </friction>
          </surface>
        </collision>
        <visual name='visual'>
          <geometry>
            <box>
              <size>1 1 1</size>
            </box>
          </geometry>
          <material>
            <script>
              <name>Gazebo/Grey</name>
              <uri>file://media/materials/scripts/gazebo.material</uri>
            </script>
          </material>
        </visual>
        <self_collide>0</self_collide>
        <enable_wind>0</enable_wind>
        <kinematic>0</kinematic>
      </link>
    </model>
    <gui fullscreen='0'>
      <camera name='user_camera'>
        <pose frame=''>31.2512 -12.2949 18.8079 -0 0.941796 2.8275</pose>
        <view_controller>orbit</view_controller>
        <projection_type>perspective</projection_type>
      </camera>
    </gui>
    <model name='my_robot'>
      <static>0</static>
      <link name='chassis'>
        <pose frame=''>0 0 0.1 0 -0 0</pose>
        <collision name='collision'>
          <geometry>
            <box>
              <size>0.4 0.2 0.1</size>
            </box>
          </geometry>
          <max_contacts>10</max_contacts>
          <surface>
            <contact>
              <ode/>
            </contact>
            <bounce/>
            <friction>
              <torsional>
                <ode/>
              </torsional>
              <ode/>
            </friction>
          </surface>
        </collision>
        <visual name='visual'>
          <geometry>
            <mesh>
              <scale>0.2 0.2 0.2</scale>
              <uri>model://my_robot/meshes/two_wheel.dae</uri>
            </mesh>
          </geometry>
        </visual>
        <collision name='caster_collision'>
          <pose frame=''>-0.34 0 -0.1 0 -0 0</pose>
          <geometry>
            <sphere>
              <radius>0.1</radius>
            </sphere>
          </geometry>
          <surface>
            <friction>
              <ode>
                <mu>0</mu>
                <mu2>0</mu2>
                <slip1>1</slip1>
                <slip2>1</slip2>
              </ode>
              <torsional>
                <ode/>
              </torsional>
            </friction>
            <contact>
              <ode/>
            </contact>
            <bounce/>
          </surface>
          <max_contacts>10</max_contacts>
        </collision>
        <visual name='caster_visual'>
          <pose frame=''>-0.34 0 -0.1 0 -0 0</pose>
          <geometry>
            <sphere>
              <radius>0.1</radius>
            </sphere>
          </geometry>
        </visual>
        <sensor name='body_contact' type='contact'>
          <contact>
            <collision>collision</collision>
            <topic>__default_topic__</topic>
          </contact>
          <update_rate>5</update_rate>
        </sensor>
        <self_collide>0</self_collide>
        <inertial>
          <inertia>
            <ixx>1</ixx>
            <ixy>0</ixy>
            <ixz>0</ixz>
            <iyy>1</iyy>
            <iyz>0</iyz>
            <izz>1</izz>
          </inertia>
          <mass>1</mass>
        </inertial>
        <enable_wind>0</enable_wind>
        <kinematic>0</kinematic>
      </link>
      <link name='left_wheel'>
        <pose frame=''>0.2 0.32 0.1 -0 1.5707 1.5707</pose>
        <collision name='collision'>
          <geometry>
            <cylinder>
              <radius>0.2</radius>
              <length>0.1</length>
            </cylinder>
          </geometry>
          <max_contacts>10</max_contacts>
          <surface>
            <contact>
              <ode/>
            </contact>
            <bounce/>
            <friction>
              <torsional>
                <ode/>
              </torsional>
              <ode/>
            </friction>
          </surface>
        </collision>
        <visual name='visual'>
          <geometry>
            <mesh>
              <scale>0.2 0.2 0.2</scale>
              <uri>model://my_robot/meshes/wheel.dae</uri>
            </mesh>
          </geometry>
        </visual>
        <sensor name='left_wheel_contact' type='contact'>
          <contact>
            <collision>collision</collision>
            <topic>__default_topic__</topic>
          </contact>
          <update_rate>5</update_rate>
        </sensor>
        <self_collide>0</self_collide>
        <inertial>
          <inertia>
            <ixx>1</ixx>
            <ixy>0</ixy>
            <ixz>0</ixz>
            <iyy>1</iyy>
            <iyz>0</iyz>
            <izz>1</izz>
          </inertia>
          <mass>1</mass>
        </inertial>
        <enable_wind>0</enable_wind>
        <kinematic>0</kinematic>
      </link>
      <link name='right_wheel'>
        <pose frame=''>0.2 -0.32 0.1 -0 1.5707 1.5707</pose>
        <collision name='collision'>
          <geometry>
            <cylinder>
              <radius>0.2</radius>
              <length>0.1</length>
            </cylinder>
          </geometry>
          <max_contacts>10</max_contacts>
          <surface>
            <contact>
              <ode/>
            </contact>
            <bounce/>
            <friction>
              <torsional>
                <ode/>
              </torsional>
              <ode/>
            </friction>
          </surface>
        </collision>
        <visual name='visual'>
          <geometry>
            <mesh>
              <scale>0.2 0.2 -0.2</scale>
              <uri>model://my_robot/meshes/wheel.dae</uri>
            </mesh>
          </geometry>
        </visual>
        <sensor name='right_wheel_contact' type='contact'>
          <contact>
            <collision>collision</collision>
            <topic>__default_topic__</topic>
          </contact>
          <update_rate>5</update_rate>
        </sensor>
        <self_collide>0</self_collide>
        <inertial>
          <inertia>
            <ixx>1</ixx>
            <ixy>0</ixy>
            <ixz>0</ixz>
            <iyy>1</iyy>
            <iyz>0</iyz>
            <izz>1</izz>
          </inertia>
          <mass>1</mass>
        </inertial>
        <enable_wind>0</enable_wind>
        <kinematic>0</kinematic>
      </link>
      <joint name='left_wheel_hinge' type='revolute'>
        <pose frame=''>0 0 -0.03 0 -0 0</pose>
        <child>left_wheel</child>
        <parent>chassis</parent>
        <axis>
          <xyz>0 1 0</xyz>
          <use_parent_model_frame>1</use_parent_model_frame>
          <limit>
            <lower>-1e+16</lower>
            <upper>1e+16</upper>
          </limit>
          <dynamics>
            <spring_reference>0</spring_reference>
            <spring_stiffness>0</spring_stiffness>
          </dynamics>
        </axis>
      </joint>
      <joint name='right_wheel_hinge' type='revolute'>
        <pose frame=''>0 0 0.03 0 -0 0</pose>
        <child>right_wheel</child>
        <parent>chassis</parent>
        <axis>
          <xyz>0 1 0</xyz>
          <use_parent_model_frame>1</use_parent_model_frame>
          <limit>
            <lower>-1e+16</lower>
            <upper>1e+16</upper>
          </limit>
          <dynamics>
            <spring_reference>0</spring_reference>
            <spring_stiffness>0</spring_stiffness>
          </dynamics>
        </axis>
      </joint>
      <link name='hokuyo::link'>
        <inertial>
          <mass>0.1</mass>
          <inertia>
            <ixx>1</ixx>
            <ixy>0</ixy>
            <ixz>0</ixz>
            <iyy>1</iyy>
            <iyz>0</iyz>
            <izz>1</izz>
          </inertia>
        </inertial>
        <visual name='visual'>
          <geometry>
            <mesh>
              <uri>model://hokuyo/meshes/hokuyo.dae</uri>
            </mesh>
          </geometry>
        </visual>
        <collision name='collision-base'>
          <pose frame=''>0 0 -0.0145 0 -0 0</pose>
          <geometry>
            <box>
              <size>0.05 0.05 0.041</size>
            </box>
          </geometry>
          <max_contacts>10</max_contacts>
          <surface>
            <contact>
              <ode/>
            </contact>
            <bounce/>
            <friction>
              <torsional>
                <ode/>
              </torsional>
              <ode/>
            </friction>
          </surface>
        </collision>
        <collision name='collision-top'>
          <pose frame=''>0 0 0.0205 0 -0 0</pose>
          <geometry>
            <cylinder>
              <radius>0.021</radius>
              <length>0.029</length>
            </cylinder>
          </geometry>
          <max_contacts>10</max_contacts>
          <surface>
            <contact>
              <ode/>
            </contact>
            <bounce/>
            <friction>
              <torsional>
                <ode/>
              </torsional>
              <ode/>
            </friction>
          </surface>
        </collision>
        <sensor name='laser' type='ray'>
          <pose frame=''>0.01 0 0.0175 0 -0 0</pose>
          <ray>
            <scan>
              <horizontal>
                <samples>640</samples>
                <resolution>1</resolution>
                <min_angle>-2.26889</min_angle>
                <max_angle>2.2689</max_angle>
              </horizontal>
              <vertical>
                <samples>1</samples>
                <min_angle>0</min_angle>
                <max_angle>0</max_angle>
              </vertical>
            </scan>
            <range>
              <min>0.08</min>
              <max>10</max>
              <resolution>0.01</resolution>
            </range>
          </ray>
          <plugin name='laser' filename='libRayPlugin.so'/>
          <always_on>1</always_on>
          <update_rate>30</update_rate>
          <visualize>1</visualize>
        </sensor>
        <pose frame=''>-0.22 0 0.25 0 -0 3.14</pose>
        <self_collide>0</self_collide>
        <enable_wind>0</enable_wind>
        <kinematic>0</kinematic>
      </link>
      <joint name='hokuyo_joint' type='fixed'>
        <child>hokuyo::link</child>
        <parent>chassis</parent>
      </joint>
      <link name='camera::link'>
        <inertial>
          <mass>0.1</mass>
          <inertia>
            <ixx>0.000166667</ixx>
            <iyy>0.000166667</iyy>
            <izz>0.000166667</izz>
            <ixy>0</ixy>
            <ixz>0</ixz>
            <iyz>0</iyz>
          </inertia>
        </inertial>
        <collision name='collision'>
          <geometry>
            <box>
              <size>0.1 0.1 0.1</size>
            </box>
          </geometry>
          <max_contacts>10</max_contacts>
          <surface>
            <contact>
              <ode/>
            </contact>
            <bounce/>
            <friction>
              <torsional>
                <ode/>
              </torsional>
              <ode/>
            </friction>
          </surface>
        </collision>
        <visual name='visual'>
          <geometry>
            <box>
              <size>0.1 0.1 0.1</size>
            </box>
          </geometry>
        </visual>
        <sensor name='camera' type='camera'>
          <camera name='__default__'>
            <horizontal_fov>1.047</horizontal_fov>
            <image>
              <width>320</width>
              <height>240</height>
            </image>
            <clip>
              <near>0.1</near>
              <far>100</far>
            </clip>
          </camera>
          <always_on>1</always_on>
          <update_rate>30</update_rate>
          <visualize>1</visualize>
        </sensor>
        <pose frame=''>-0.2 0 0.15 0 -0 3.14</pose>
        <self_collide>0</self_collide>
        <enable_wind>0</enable_wind>
        <kinematic>0</kinematic>
      </link>
      <joint name='camera_joint' type='fixed'>
        <child>camera::link</child>
        <parent>chassis</parent>
      </joint>
      <plugin name='twowheel' filename='libtwowheel.so'/>
      <pose frame=''>14.8315 -6.3661 0 0 -0 0</pose>
    </model>
    <model name='my_robot_four'>
      <static>0</static>
      <link name='chassis'>
        <pose frame=''>0 0 0.2 0 -0 0</pose>
        <collision name='collision'>
          <geometry>
            <box>
              <size>0.4 0.2 0.1</size>
            </box>
          </geometry>
          <max_contacts>10</max_contacts>
          <surface>
            <contact>
              <ode/>
            </contact>
            <bounce/>
            <friction>
              <torsional>
                <ode/>
              </torsional>
              <ode/>
            </friction>
          </surface>
        </collision>
        <visual name='visual'>
          <geometry>
            <mesh>
              <scale>0.2 0.2 0.2</scale>
              <uri>model://my_robot_four/meshes/four_wheel.dae</uri>
            </mesh>
          </geometry>
        </visual>
        <collision name='caster_collision'>
          <pose frame=''>-0.34 0 -0.1 0 -0 0</pose>
          <geometry>
            <sphere>
              <radius>0.1</radius>
            </sphere>
          </geometry>
          <surface>
            <friction>
              <ode>
                <mu>0</mu>
                <mu2>0</mu2>
                <slip1>1</slip1>
                <slip2>1</slip2>
              </ode>
              <torsional>
                <ode/>
              </torsional>
            </friction>
            <contact>
              <ode/>
            </contact>
            <bounce/>
          </surface>
          <max_contacts>10</max_contacts>
        </collision>
        <visual name='caster_visual'>
          <pose frame=''>-0.34 0 -0.1 0 -0 0</pose>
          <geometry>
            <sphere>
              <radius>0.1</radius>
            </sphere>
          </geometry>
        </visual>
        <sensor name='body_contact' type='contact'>
          <contact>
            <collision>collision</collision>
            <topic>__default_topic__</topic>
          </contact>
          <update_rate>5</update_rate>
        </sensor>
        <self_collide>0</self_collide>
        <inertial>
          <inertia>
            <ixx>1</ixx>
            <ixy>0</ixy>
            <ixz>0</ixz>
            <iyy>1</iyy>
            <iyz>0</iyz>
            <izz>1</izz>
          </inertia>
          <mass>1</mass>
        </inertial>
        <enable_wind>0</enable_wind>
        <kinematic>0</kinematic>
      </link>
      <link name='left_wheel'>
        <pose frame=''>0.25 0.32 0.1 -0 1.5707 1.5707</pose>
        <collision name='collision'>
          <geometry>
            <cylinder>
              <radius>0.2</radius>
              <length>0.1</length>
            </cylinder>
          </geometry>
          <max_contacts>10</max_contacts>
          <surface>
            <contact>
              <ode/>
            </contact>
            <bounce/>
            <friction>
              <torsional>
                <ode/>
              </torsional>
              <ode/>
            </friction>
          </surface>
        </collision>
        <visual name='visual'>
          <geometry>
            <mesh>
              <scale>0.2 0.2 0.2</scale>
              <uri>model://my_robot_four/meshes/wheel.dae</uri>
            </mesh>
          </geometry>
        </visual>
        <sensor name='left_wheel_contact' type='contact'>
          <contact>
            <collision>collision</collision>
            <topic>__default_topic__</topic>
          </contact>
          <update_rate>5</update_rate>
        </sensor>
        <self_collide>0</self_collide>
        <inertial>
          <inertia>
            <ixx>1</ixx>
            <ixy>0</ixy>
            <ixz>0</ixz>
            <iyy>1</iyy>
            <iyz>0</iyz>
            <izz>1</izz>
          </inertia>
          <mass>1</mass>
        </inertial>
        <enable_wind>0</enable_wind>
        <kinematic>0</kinematic>
      </link>
      <link name='right_wheel'>
        <pose frame=''>0.25 -0.32 0.1 -0 1.5707 1.5707</pose>
        <collision name='collision'>
          <geometry>
            <cylinder>
              <radius>0.2</radius>
              <length>0.1</length>
            </cylinder>
          </geometry>
          <max_contacts>10</max_contacts>
          <surface>
            <contact>
              <ode/>
            </contact>
            <bounce/>
            <friction>
              <torsional>
                <ode/>
              </torsional>
              <ode/>
            </friction>
          </surface>
        </collision>
        <visual name='visual'>
          <geometry>
            <mesh>
              <scale>0.2 0.2 -0.2</scale>
              <uri>model://my_robot_four/meshes/wheel.dae</uri>
            </mesh>
          </geometry>
        </visual>
        <sensor name='right_wheel_contact' type='contact'>
          <contact>
            <collision>collision</collision>
            <topic>__default_topic__</topic>
          </contact>
          <update_rate>5</update_rate>
        </sensor>
        <self_collide>0</self_collide>
        <inertial>
          <inertia>
            <ixx>1</ixx>
            <ixy>0</ixy>
            <ixz>0</ixz>
            <iyy>1</iyy>
            <iyz>0</iyz>
            <izz>1</izz>
          </inertia>
          <mass>1</mass>
        </inertial>
        <enable_wind>0</enable_wind>
        <kinematic>0</kinematic>
      </link>
      <link name='right_wheel1'>
        <pose frame=''>-0.25 -0.32 0.1 -0 1.5707 1.5707</pose>
        <collision name='collision'>
          <geometry>
            <cylinder>
              <radius>0.2</radius>
              <length>0.1</length>
            </cylinder>
          </geometry>
          <max_contacts>10</max_contacts>
          <surface>
            <contact>
              <ode/>
            </contact>
            <bounce/>
            <friction>
              <torsional>
                <ode/>
              </torsional>
              <ode/>
            </friction>
          </surface>
        </collision>
        <visual name='visual'>
          <geometry>
            <mesh>
              <scale>0.2 0.2 -0.2</scale>
              <uri>model://my_robot_four/meshes/wheel.dae</uri>
            </mesh>
          </geometry>
        </visual>
        <self_collide>0</self_collide>
        <inertial>
          <inertia>
            <ixx>1</ixx>
            <ixy>0</ixy>
            <ixz>0</ixz>
            <iyy>1</iyy>
            <iyz>0</iyz>
            <izz>1</izz>
          </inertia>
          <mass>1</mass>
        </inertial>
        <enable_wind>0</enable_wind>
        <kinematic>0</kinematic>
      </link>
      <link name='left_wheel1'>
        <pose frame=''>-0.25 0.32 0.1 -0 1.5707 1.5707</pose>
        <collision name='collision'>
          <geometry>
            <cylinder>
              <radius>0.2</radius>
              <length>0.1</length>
            </cylinder>
          </geometry>
          <max_contacts>10</max_contacts>
          <surface>
            <contact>
              <ode/>
            </contact>
            <bounce/>
            <friction>
              <torsional>
                <ode/>
              </torsional>
              <ode/>
            </friction>
          </surface>
        </collision>
        <visual name='visual'>
          <geometry>
            <mesh>
              <scale>0.2 0.2 0.2</scale>
              <uri>model://my_robot_four/meshes/wheel.dae</uri>
            </mesh>
          </geometry>
        </visual>
        <self_collide>0</self_collide>
        <inertial>
          <inertia>
            <ixx>1</ixx>
            <ixy>0</ixy>
            <ixz>0</ixz>
            <iyy>1</iyy>
            <iyz>0</iyz>
            <izz>1</izz>
          </inertia>
          <mass>1</mass>
        </inertial>
        <enable_wind>0</enable_wind>
        <kinematic>0</kinematic>
      </link>
      <joint name='left_wheel_hinge' type='revolute'>
        <pose frame=''>0 0 -0.03 0 -0 0</pose>
        <child>left_wheel</child>
        <parent>chassis</parent>
        <axis>
          <xyz>0 1 0</xyz>
          <use_parent_model_frame>1</use_parent_model_frame>
          <limit>
            <lower>-1e+16</lower>
            <upper>1e+16</upper>
          </limit>
          <dynamics>
            <spring_reference>0</spring_reference>
            <spring_stiffness>0</spring_stiffness>
          </dynamics>
        </axis>
      </joint>
      <joint name='right_wheel_hinge' type='revolute'>
        <pose frame=''>0 0 0.03 0 -0 0</pose>
        <child>right_wheel</child>
        <parent>chassis</parent>
        <axis>
          <xyz>0 1 0</xyz>
          <use_parent_model_frame>1</use_parent_model_frame>
          <limit>
            <lower>-1e+16</lower>
            <upper>1e+16</upper>
          </limit>
          <dynamics>
            <spring_reference>0</spring_reference>
            <spring_stiffness>0</spring_stiffness>
          </dynamics>
        </axis>
      </joint>
      <joint name='left_wheel_hinge1' type='revolute'>
        <pose frame=''>0 0 -0.03 0 -0 0</pose>
        <child>left_wheel1</child>
        <parent>chassis</parent>
        <axis>
          <xyz>0 1 0</xyz>
          <use_parent_model_frame>1</use_parent_model_frame>
          <limit>
            <lower>-1e+16</lower>
            <upper>1e+16</upper>
          </limit>
          <dynamics>
            <spring_reference>0</spring_reference>
            <spring_stiffness>0</spring_stiffness>
          </dynamics>
        </axis>
      </joint>
      <joint name='right_wheel_hinge1' type='revolute'>
        <pose frame=''>0 0 0.03 0 -0 0</pose>
        <child>right_wheel1</child>
        <parent>chassis</parent>
        <axis>
          <xyz>0 1 0</xyz>
          <use_parent_model_frame>1</use_parent_model_frame>
          <limit>
            <lower>-1e+16</lower>
            <upper>1e+16</upper>
          </limit>
          <dynamics>
            <spring_reference>0</spring_reference>
            <spring_stiffness>0</spring_stiffness>
          </dynamics>
        </axis>
      </joint>
      <plugin name='twowheel' filename='libtwowheel.so'/>
      <pose frame=''>16.6812 -7.53374 0 0 -0 0</pose>
    </model>
    <model name='my_robot_six'>
      <static>0</static>
      <link name='chassis'>
        <pose frame=''>0 0 0.2 0 -0 0</pose>
        <collision name='collision'>
          <geometry>
            <box>
              <size>0.4 0.2 0.1</size>
            </box>
          </geometry>
          <max_contacts>10</max_contacts>
          <surface>
            <contact>
              <ode/>
            </contact>
            <bounce/>
            <friction>
              <torsional>
                <ode/>
              </torsional>
              <ode/>
            </friction>
          </surface>
        </collision>
        <visual name='visual'>
          <geometry>
            <mesh>
              <scale>0.2 0.2 0.2</scale>
              <uri>model://my_robot_six/meshes/six_wheel.dae</uri>
            </mesh>
          </geometry>
        </visual>
        <collision name='caster_collision'>
          <pose frame=''>-0.34 0 -0.1 0 -0 0</pose>
          <geometry>
            <sphere>
              <radius>0.1</radius>
            </sphere>
          </geometry>
          <surface>
            <friction>
              <ode>
                <mu>0</mu>
                <mu2>0</mu2>
                <slip1>1</slip1>
                <slip2>1</slip2>
              </ode>
              <torsional>
                <ode/>
              </torsional>
            </friction>
            <contact>
              <ode/>
            </contact>
            <bounce/>
          </surface>
          <max_contacts>10</max_contacts>
        </collision>
        <visual name='caster_visual'>
          <pose frame=''>-0.34 0 -0.1 0 -0 0</pose>
          <geometry>
            <sphere>
              <radius>0.1</radius>
            </sphere>
          </geometry>
        </visual>
        <sensor name='body_contact' type='contact'>
          <contact>
            <collision>collision</collision>
            <topic>__default_topic__</topic>
          </contact>
          <update_rate>5</update_rate>
        </sensor>
        <self_collide>0</self_collide>
        <inertial>
          <inertia>
            <ixx>1</ixx>
            <ixy>0</ixy>
            <ixz>0</ixz>
            <iyy>1</iyy>
            <iyz>0</iyz>
            <izz>1</izz>
          </inertia>
          <mass>1</mass>
        </inertial>
        <enable_wind>0</enable_wind>
        <kinematic>0</kinematic>
      </link>
      <link name='scooper'>
        <pose frame=''>-0.85 0 0.1 0 -0 0</pose>
        <collision name='collision'>
          <geometry>
            <mesh>
              <scale>0.2 0.2 0.2</scale>
              <uri>model://my_robot_six/meshes/scoop.dae</uri>
            </mesh>
          </geometry>
          <max_contacts>10</max_contacts>
          <surface>
            <contact>
              <ode/>
            </contact>
            <bounce/>
            <friction>
              <torsional>
                <ode/>
              </torsional>
              <ode/>
            </friction>
          </surface>
        </collision>
        <visual name='visual'>
          <geometry>
            <mesh>
              <scale>0.2 0.2 0.2</scale>
              <uri>model://my_robot_six/meshes/scoop.dae</uri>
            </mesh>
          </geometry>
        </visual>
        <self_collide>0</self_collide>
        <inertial>
          <inertia>
            <ixx>1</ixx>
            <ixy>0</ixy>
            <ixz>0</ixz>
            <iyy>1</iyy>
            <iyz>0</iyz>
            <izz>1</izz>
          </inertia>
          <mass>1</mass>
        </inertial>
        <enable_wind>0</enable_wind>
        <kinematic>0</kinematic>
      </link>
      <link name='left_wheel'>
        <pose frame=''>0.5 0.32 0.1 -0 1.5707 1.5707</pose>
        <collision name='collision'>
          <geometry>
            <cylinder>
              <radius>0.2</radius>
              <length>0.1</length>
            </cylinder>
          </geometry>
          <max_contacts>10</max_contacts>
          <surface>
            <contact>
              <ode/>
            </contact>
            <bounce/>
            <friction>
              <torsional>
                <ode/>
              </torsional>
              <ode/>
            </friction>
          </surface>
        </collision>
        <visual name='visual'>
          <geometry>
            <mesh>
              <scale>0.2 0.2 0.2</scale>
              <uri>model://my_robot_six/meshes/wheel.dae</uri>
            </mesh>
          </geometry>
        </visual>
        <sensor name='left_wheel_contact' type='contact'>
          <contact>
            <collision>collision</collision>
            <topic>__default_topic__</topic>
          </contact>
          <update_rate>5</update_rate>
        </sensor>
        <self_collide>0</self_collide>
        <inertial>
          <inertia>
            <ixx>1</ixx>
            <ixy>0</ixy>
            <ixz>0</ixz>
            <iyy>1</iyy>
            <iyz>0</iyz>
            <izz>1</izz>
          </inertia>
          <mass>1</mass>
        </inertial>
        <enable_wind>0</enable_wind>
        <kinematic>0</kinematic>
      </link>
      <link name='right_wheel'>
        <pose frame=''>0.5 -0.32 0.1 -0 1.5707 1.5707</pose>
        <collision name='collision'>
          <geometry>
            <cylinder>
              <radius>0.2</radius>
              <length>0.1</length>
            </cylinder>
          </geometry>
          <max_contacts>10</max_contacts>
          <surface>
            <contact>
              <ode/>
            </contact>
            <bounce/>
            <friction>
              <torsional>
                <ode/>
              </torsional>
              <ode/>
            </friction>
          </surface>
        </collision>
        <visual name='visual'>
          <geometry>
            <mesh>
              <scale>0.2 0.2 -0.2</scale>
              <uri>model://my_robot_six/meshes/wheel.dae</uri>
            </mesh>
          </geometry>
        </visual>
        <sensor name='right_wheel_contact' type='contact'>
          <contact>
            <collision>collision</collision>
            <topic>__default_topic__</topic>
          </contact>
          <update_rate>5</update_rate>
        </sensor>
        <self_collide>0</self_collide>
        <inertial>
          <inertia>
            <ixx>1</ixx>
            <ixy>0</ixy>
            <ixz>0</ixz>
            <iyy>1</iyy>
            <iyz>0</iyz>
            <izz>1</izz>
          </inertia>
          <mass>1</mass>
        </inertial>
        <enable_wind>0</enable_wind>
        <kinematic>0</kinematic>
      </link>
      <link name='right_wheel1'>
        <pose frame=''>0.05 -0.32 0.1 -0 1.5707 1.5707</pose>
        <collision name='collision'>
          <geometry>
            <cylinder>
              <radius>0.2</radius>
              <length>0.1</length>
            </cylinder>
          </geometry>
          <max_contacts>10</max_contacts>
          <surface>
            <contact>
              <ode/>
            </contact>
            <bounce/>
            <friction>
              <torsional>
                <ode/>
              </torsional>
              <ode/>
            </friction>
          </surface>
        </collision>
        <visual name='visual'>
          <geometry>
            <mesh>
              <scale>0.2 0.2 -0.2</scale>
              <uri>model://my_robot_six/meshes/wheel.dae</uri>
            </mesh>
          </geometry>
        </visual>
        <self_collide>0</self_collide>
        <inertial>
          <inertia>
            <ixx>1</ixx>
            <ixy>0</ixy>
            <ixz>0</ixz>
            <iyy>1</iyy>
            <iyz>0</iyz>
            <izz>1</izz>
          </inertia>
          <mass>1</mass>
        </inertial>
        <enable_wind>0</enable_wind>
        <kinematic>0</kinematic>
      </link>
      <link name='left_wheel1'>
        <pose frame=''>0.05 0.32 0.1 -0 1.5707 1.5707</pose>
        <collision name='collision'>
          <geometry>
            <cylinder>
              <radius>0.2</radius>
              <length>0.1</length>
            </cylinder>
          </geometry>
          <max_contacts>10</max_contacts>
          <surface>
            <contact>
              <ode/>
            </contact>
            <bounce/>
            <friction>
              <torsional>
                <ode/>
              </torsional>
              <ode/>
            </friction>
          </surface>
        </collision>
        <visual name='visual'>
          <geometry>
            <mesh>
              <scale>0.2 0.2 0.2</scale>
              <uri>model://my_robot_six/meshes/wheel.dae</uri>
            </mesh>
          </geometry>
        </visual>
        <self_collide>0</self_collide>
        <inertial>
          <inertia>
            <ixx>1</ixx>
            <ixy>0</ixy>
            <ixz>0</ixz>
            <iyy>1</iyy>
            <iyz>0</iyz>
            <izz>1</izz>
          </inertia>
          <mass>1</mass>
        </inertial>
        <enable_wind>0</enable_wind>
        <kinematic>0</kinematic>
      </link>
      <link name='right_wheel2'>
        <pose frame=''>-0.45 -0.32 0.1 -0 1.5707 1.5707</pose>
        <collision name='collision'>
          <geometry>
            <cylinder>
              <radius>0.2</radius>
              <length>0.1</length>
            </cylinder>
          </geometry>
          <max_contacts>10</max_contacts>
          <surface>
            <contact>
              <ode/>
            </contact>
            <bounce/>
            <friction>
              <torsional>
                <ode/>
              </torsional>
              <ode/>
            </friction>
          </surface>
        </collision>
        <visual name='visual'>
          <geometry>
            <mesh>
              <scale>0.2 0.2 -0.2</scale>
              <uri>model://my_robot_six/meshes/wheel.dae</uri>
            </mesh>
          </geometry>
        </visual>
        <self_collide>0</self_collide>
        <inertial>
          <inertia>
            <ixx>1</ixx>
            <ixy>0</ixy>
            <ixz>0</ixz>
            <iyy>1</iyy>
            <iyz>0</iyz>
            <izz>1</izz>
          </inertia>
          <mass>1</mass>
        </inertial>
        <enable_wind>0</enable_wind>
        <kinematic>0</kinematic>
      </link>
      <link name='left_wheel2'>
        <pose frame=''>-0.45 0.32 0.1 -0 1.5707 1.5707</pose>
        <collision name='collision'>
          <geometry>
            <cylinder>
              <radius>0.2</radius>
              <length>0.1</length>
            </cylinder>
          </geometry>
          <max_contacts>10</max_contacts>
          <surface>
            <contact>
              <ode/>
            </contact>
            <bounce/>
            <friction>
              <torsional>
                <ode/>
              </torsional>
              <ode/>
            </friction>
          </surface>
        </collision>
        <visual name='visual'>
          <geometry>
            <mesh>
              <scale>0.2 0.2 0.2</scale>
              <uri>model://my_robot_six/meshes/wheel.dae</uri>
            </mesh>
          </geometry>
        </visual>
        <self_collide>0</self_collide>
        <inertial>
          <inertia>
            <ixx>1</ixx>
            <ixy>0</ixy>
            <ixz>0</ixz>
            <iyy>1</iyy>
            <iyz>0</iyz>
            <izz>1</izz>
          </inertia>
          <mass>1</mass>
        </inertial>
        <enable_wind>0</enable_wind>
        <kinematic>0</kinematic>
      </link>
      <joint name='left_wheel_hinge' type='revolute'>
        <pose frame=''>0 0 -0.03 0 -0 0</pose>
        <child>left_wheel</child>
        <parent>chassis</parent>
        <axis>
          <xyz>0 1 0</xyz>
          <use_parent_model_frame>1</use_parent_model_frame>
          <limit>
            <lower>-1e+16</lower>
            <upper>1e+16</upper>
          </limit>
          <dynamics>
            <spring_reference>0</spring_reference>
            <spring_stiffness>0</spring_stiffness>
          </dynamics>
        </axis>
      </joint>
      <joint name='right_wheel_hinge' type='revolute'>
        <pose frame=''>0 0 0.03 0 -0 0</pose>
        <child>right_wheel</child>
        <parent>chassis</parent>
        <axis>
          <xyz>0 1 0</xyz>
          <use_parent_model_frame>1</use_parent_model_frame>
          <limit>
            <lower>-1e+16</lower>
            <upper>1e+16</upper>
          </limit>
          <dynamics>
            <spring_reference>0</spring_reference>
            <spring_stiffness>0</spring_stiffness>
          </dynamics>
        </axis>
      </joint>
      <joint name='left_wheel_hinge1' type='revolute'>
        <pose frame=''>0 0 -0.03 0 -0 0</pose>
        <child>left_wheel1</child>
        <parent>chassis</parent>
        <axis>
          <xyz>0 1 0</xyz>
          <use_parent_model_frame>1</use_parent_model_frame>
          <limit>
            <lower>-1e+16</lower>
            <upper>1e+16</upper>
          </limit>
          <dynamics>
            <spring_reference>0</spring_reference>
            <spring_stiffness>0</spring_stiffness>
          </dynamics>
        </axis>
      </joint>
      <joint name='right_wheel_hinge1' type='revolute'>
        <pose frame=''>0 0 0.03 0 -0 0</pose>
        <child>right_wheel1</child>
        <parent>chassis</parent>
        <axis>
          <xyz>0 1 0</xyz>
          <use_parent_model_frame>1</use_parent_model_frame>
          <limit>
            <lower>-1e+16</lower>
            <upper>1e+16</upper>
          </limit>
          <dynamics>
            <spring_reference>0</spring_reference>
            <spring_stiffness>0</spring_stiffness>
          </dynamics>
        </axis>
      </joint>
      <joint name='left_wheel_hinge2' type='revolute'>
        <pose frame=''>0 0 -0.03 0 -0 0</pose>
        <child>left_wheel2</child>
        <parent>chassis</parent>
        <axis>
          <xyz>0 1 0</xyz>
          <use_parent_model_frame>1</use_parent_model_frame>
          <limit>
            <lower>-1e+16</lower>
            <upper>1e+16</upper>
          </limit>
          <dynamics>
            <spring_reference>0</spring_reference>
            <spring_stiffness>0</spring_stiffness>
          </dynamics>
        </axis>
      </joint>
      <joint name='right_wheel_hinge2' type='revolute'>
        <pose frame=''>0 0 0.03 0 -0 0</pose>
        <child>right_wheel2</child>
        <parent>chassis</parent>
        <axis>
          <xyz>0 1 0</xyz>
          <use_parent_model_frame>1</use_parent_model_frame>
          <limit>
            <lower>-1e+16</lower>
            <upper>1e+16</upper>
          </limit>
          <dynamics>
            <spring_reference>0</spring_reference>
            <spring_stiffness>0</spring_stiffness>
          </dynamics>
        </axis>
      </joint>
      <joint name='scoop_hinge' type='revolute'>
        <pose frame=''>0 0 0 0 -0 0</pose>
        <child>scooper</child>
        <parent>chassis</parent>
        <axis>
          <xyz>1 0 0</xyz>
          <use_parent_model_frame>1</use_parent_model_frame>
          <limit>
            <lower>-1e+16</lower>
            <upper>1e+16</upper>
          </limit>
          <dynamics>
            <spring_reference>0</spring_reference>
            <spring_stiffness>0</spring_stiffness>
          </dynamics>
        </axis>
      </joint>
      <plugin name='twowheel' filename='libtwowheel.so'/>
      <pose frame=''>18.2673 -5.60996 0 0 -0 0</pose>
    </model>
  </world>
</sdf>
